Workbook

Sheet actual
A1: Sr No. | B1: Name | C1: Category | D1: Product Name | E1: Region | F1: City | G1: State | H1: Gender | I1: Quantity | J1: Rate | K1: Amount | N1: Region | O1: City | S1: Product Name
A2: 1 | B2: Bharat Innovations | C2: Electronic | D2: Speaker | E2: North | F2: Delhi | G2: Delhi | H2: Male | I2: 4292 | J2: 2 | K2: 2 | S2: Speaker
A3: 2 | B3: Green Leaf Enterprises | C3: Electronic | D3: Car accessories | E3: West | F3: Mumbai | G3: Maharashtra | H3: Male | I3: 8037 | J3: 3 | K3: 3 | S3: Car accessories
A4: 3 | B4: Urban Pulse Technologies | C4: Electronic | D4: Earbuds | E4: East | F4: Kolkata | G4: West Bengal | H4: Male | I4: 2415 | J4: 4 | K4: 4 | S4: Earbuds
A5: 4 | B5: Mystic India Exports | C5: Electronic | D5: Earbuds | E5: South | F5: Chennai | G5: Tamil Nadu | H5: Male | I5: 3941 | J5: 5 | K5: 5 | S5: Women dress
A6: 5 | B6: Golden Horizon Ventures | C6: Fashion | D6: Women dress | E6: South | F6: Bengaluru | G6: Karnataka | H6: Male | I6: 4607 | J6: 6 | K6: 6 | S6: Saree
A7: 6 | B7: Eternal Traditions | C7: Fashion | D7: Women dress | E7: South | F7: Hyderabad | G7: Telangana | H7: Male | I7: 4261 | J7: 7 | K7: 7 | S7: Male dress
A8: 7 | B8: Apex Solutions | C8: Fashion | D8: Saree | E8: West | F8: Ahmedabad | G8: Gujarat | H8: Male | I8: 9084 | J8: 8 | K8: 8 | S8: TV
A9: 8 | B9: Harmony Foods | C9: Fashion | D9: Women dress | E9: West | F9: Pune | G9: Maharashtra | H9: Male | I9: 6694 | J9: 9 | K9: 9 | S9: Laptop
A10: 9 | B10: Pure Essence Skincare | C10: Electronic | D10: Speaker | E10: North | F10: Jaipur | G10: Rajasthan | H10: Female | I10: 2678 | J10: 10 | K10: 10 | S10: Suit
A11: 10 | B11: Zenith Construction Co. | C11: Electronic | D11: Speaker | E11: West | F11: Surat | G11: Gujarat | H11: Female | I11: 1631 | J11: 11 | K11: 11 | S11: Home décor
A12: 11 | B12: Radiant Health Systems | C12: Electronic | D12: Speaker | E12: North | F12: Lucknow | G12: Uttar Pradesh | H12: Female | I12: 4171 | J12: 12 | K12: 12
A13: 12 | B13: Divine Creations | C13: Electronic | D13: Speaker | E13: North | F13: Kanpur | G13: Uttar Pradesh | H13: Female | I13: 4283 | J13: 13 | K13: 13
A14: 13 | B14: Metro Tech Solutions | C14: Electronic | D14: speaker | E14: West | F14: Nagpur | G14: Maharashtra | H14: Female | I14: 4249 | J14: 14 | K14: 14
A15: 14 | B15: True Path Logistics | C15: Electronic | D15: Speaker | E15: Central | F15: Indore | G15: Madhya Pradesh | H15: Female | I15: 1902 | J15: 15 | K15: 15
A16: 20 | B16: Classic Cuisines | C16: Fashion | D16: Male dress | E16: West | F16: Vadodara | G16: Gujarat | H16: Male | I16: 5603 | J16: 21 | K16: 21
A17: 21 | B17: Bold Ventures | C17: Fashion | D17: Male dress | E17: North | F17: Agra | G17: Uttar Pradesh | H17: Male | I17: 9513 | J17: 22 | K17: 22
A18: 22 | B18: Prestige Automobiles | C18: Electronic | D18: TV | E18: North | F18: Meerut | G18: Uttar Pradesh | H18: Male | I18: 9633 | J18: 23 | K18: 23
A19: 23 | B19: Elite Marketing Solutions | C19: Electronic | D19: TV | E19: South | F19: Coimbatore | G19: Tamil Nadu | H19: Male | I19: 4332 | J19: 24 | K19: 24
A20: 24 | B20: Natural Bliss Beverages | C20: Electronic | D20: TV | E20: South | F20: Madurai | G20: Tamil Nadu | H20: Male | I20: 1995 | J20: 25 | K20: 25
A21: 25 | B21: Crystal Clear Solutions | C21: Electronic | D21: TV | E21: North | F21: Jodhpur | G21: Rajasthan | H21: Female | I21: 3691 | J21: 26 | K21: 26
A22: 26 | B22: Modern Trends Fashion | C22: Electronic | D22: TV | E22: North | F22: Varanasi | G22: Uttar Pradesh | H22: Female | I22: 2570 | J22: 27 | K22: 27
A23: 27 | B23: Heritage Crafts | C23: Electronic | D23: TV | E23: East | F23: Ranchi | G23: Jharkhand | H23: Female | I23: 2952 | J23: 28 | K23: 28
... A326: 330 | B326: Legacy Health Co. | C326: Fashion | D326: Suit | E326: North | F326: Amritsar | G326: Punjab | H326: Male | I326: 5246 | J326: 331 | K326: 331
I327: =SUBTOTAL(9,I2:I326) -> 1830286 | K327: =SUBTOTAL(9,K2:K326) -> 54855

Sheet pivot table
F1: CITY
B2: SALES | F2: Delhi | G2: {=SUMIF(actual!$F$2:$F$326,'pivot table'!F2:F40,actual!$K$2:$K$326)} -> 914 | H2: =G2/$G$41 -> 0.016662109 | J2: STATE
B3: TARGET | C3: =[1]target!D318 -> 22276800 | D3: =C3/$C$5 -> 0.92407685 | F3: Mumbai | G3: 921 | H3: =G3/$G$41 -> 0.016789718 | J3: Delhi | K3: {=SUMIF(actual!$G$2:$G$326,'pivot table'!J3:J23,actual!$J$2:$J$326)} -> 914 | L3: =K3/$K$24 -> 0.016662109
B4: ACTAUL | C4: =actual!I327 -> 1830286 | D4: =C4/$C$5 -> 0.075923154 | F4: Kolkata | G4: 2341 | H4: =G4/$G$41 -> 0.042676146 | J4: Maharashtra | K4: 4889 | L4: =K4/$K$24 -> 0.089125877
B5: TOTAL | C5: =SUM(C3:C4) -> 24107086 | D5: =SUM(D3:D4) -> 1 | F5: Chennai | G5: 652 | H5: =G5/$G$41 -> 0.011885881 | J5: West Bengal | K5: 5973 | L5: =K5/$K$24 -> 0.10888707
F6: Bengaluru | G6: 658 | H6: =G6/$G$41 -> 0.01199526 | J6: Tamil Nadu | K6: 4348 | L6: =K6/$K$24 -> 0.079263513
B7: REGION | F7: Hyderabad | G7: 664 | H7: =G7/$G$41 -> 0.01210464 | J7: Karnataka | K7: 1765 | L7: =K7/$K$24 -> 0.032175736
B8: North | C8: {=SUMIF(actual!$E$2:$E$326,'pivot table'!B8:B14,actual!$I$2:$I$326)} -> 575296 | D8: =C8/$C$15 -> 0.31432028 | F8: Ahmedabad | G8: 670 | H8: =G8/$G$41 -> 0.012214019 | J8: Telangana | K8: 664 | L8: =K8/$K$24 -> 0.01210464
B9: West | C9: 324858 | D9: =C9/$C$15 -> 0.17749029 | F9: Pune | G9: 676 | H9: =G9/$G$41 -> 0.012323398 | J9: Gujarat | K9: 3171 | L9: =K9/$K$24 -> 0.057806946
B10: East | C10: 322649 | D10: =C10/$C$15 -> 0.17628338 | F10: Jaipur | G10: 682 | H10: =G10/$G$41 -> 0.012432777 | J10: Rajasthan | K10: 2545 | L10: =K10/$K$24 -> 0.046395041
B11: South | C11: 343381 | D11: =C11/$C$15 -> 0.18761057 | F11: Surat | G11: 688 | H11: =G11/$G$41 -> 0.012542157 | J11: Uttar Pradesh | K11: 7228 | L11: =K11/$K$24 -> 0.13176556
B12: Central | C12: 176039 | D12: =C12/$C$15 -> 0.096181143 | F12: Lucknow | G12: 694 | H12: =G12/$G$41 -> 0.012651536 | J12: Madhya Pradesh | K12: 3128 | L12: =K12/$K$24 -> 0.057023061
B13: Northeast | C13: 51602 | D13: =C13/$C$15 -> 0.028193408 | F13: Kanpur | G13: 700 | H13: =G13/$G$41 -> 0.012760915 | J13: Jharkhand | K13: 3902 | L13: =K13/$K$24 -> 0.071132987
B14: North (UT) | C14: 36461 | D14: =C14/$C$15 -> 0.01992093 | F14: Nagpur | G14: 706 | H14: =G14/$G$41 -> 0.012870294 | J14: Himachal Pradesh | K14: 2222 | L14: =K14/$K$24 -> 0.040506791
B15: TOTAL | C15: =SUM(_xlfn.ANCHORARRAY(C8)) -> 1830286 | D15: =C15/$C$15 -> 1 | F15: Indore | G15: 712 | H15: =G15/$G$41 -> 0.012979674 | J15: Uttarakhand | K15: 2233 | L15: =K15/$K$24 -> 0.040707319
F16: Vadodara | G16: 1813 | H16: =G16/$G$41 -> 0.03305077 | J16: Assam | K16: 2273 | L16: =K16/$K$24 -> 0.041436514
B17: GENDER | F17: Agra | G17: 1823 | H17: =G17/$G$41 -> 0.033233069 | J17: Punjab | K17: 2537 | L17: =K17/$K$24 -> 0.046249202
B18: MALE | C18: {=SUMIF(actual!$H$2:$H$326,'pivot table'!B18:B19,actual!$K$2:$K$326)} -> 23867 | D18: =C18/$C$20 -> 0.43509252 | F18: Meerut | G18: 1833 | H18: =G18/$G$41 -> 0.033415368 | J18: Chhattisgarh | K18: 2217 | L18: =K18/$K$24 -> 0.040415641
B19: FEMALE | C19: 30988 | D19: =C19/$C$20 -> 0.56490748 | F19: Coimbatore | G19: 1843 | H19: =G19/$G$41 -> 0.033597667 | J19: Chandigarh | K19: 707 | L19: =K19/$K$24 -> 0.012888524
B20: Total | C20: =SUM(_xlfn.ANCHORARRAY(C18)) -> 54855 | D20: =C20/$C$20 -> 1 | F20: Madurai | G20: 1853 | H20: =G20/$G$41 -> 0.033779965 | J20: Andhra Pradesh | K20: 717 | L20: =K20/$K$24 -> 0.013070823
F21: Jodhpur | G21: 1863 | H21: =G21/$G$41 -> 0.033962264 | J21: Bihar | K21: 924 | L21: =K21/$K$24 -> 0.016844408
B22: PRODUCT NAME | F22: Varanasi | G22: 2178 | H22: =G22/$G$41 -> 0.039704676 | J22: Kerala | K22: 2171 | L22: =K22/$K$24 -> 0.039577067
B23: Speaker | C23: {=SUMIF(actual!$D$2:$D$326,'pivot table'!B23:B32,actual!$I$2:$I$326)} -> 65228 | D23: =C23/$C$33 -> 0.035638146 | F23: Ranchi | G23: 2189 | H23: =G23/$G$41 -> 0.039905205 | J23: palestine | K23: 327 | L23: =K23/$K$24 -> 0.0059611704
B24: Car accessories | C24: 124096 | D24: =C24/$C$33 -> 0.067801426 | F24: Kochi | G24: 2200 | H24: =G24/$G$41 -> 0.040105733 | J24: TOTAL | K24: =SUM(_xlfn.ANCHORARRAY(K3)) -> 54855 | L24: =K24/$K$24 -> 1
B25: Earbuds | C25: 23581 | D25: =C25/$C$33 -> 0.012883779 | F25: Aurangabad | G25: 2211 | H25: =G25/$G$41 -> 0.040306262
B26: Women dress | C26: 38750 | D26: =C26/$C$33 -> 0.021171555 | F26: Shimla | G26: 2222 | H26: =G26/$G$41 -> 0.040506791 | J26: CATEGORY
B27: Saree | C27: 456645 | D27: =C27/$C$33 -> 0.24949379 | F27: Dehradun | G27: 2233 | H27: =G27/$G$41 -> 0.040707319 | J27: Electronic | K27: {=SUMIF(actual!$C$2:$C$326,'pivot table'!J27:J29,actual!$I$2:$I$326)} -> 561713 | L27: =K27/$K$30 -> 0.30689903
B28: Male dress | C28: 50077 | D28: =C28/$C$33 -> 0.027360205 | F28: Guwahati | G28: 2244 | H28: =G28/$G$41 -> 0.040907848 | J28: Fashion | K28: 852849 | L28: =K28/$K$30 -> 0.46596488
B29: TV | C29: 140972 | D29: =C29/$C$33 -> 0.077021842 | F29: Amritsar | G29: 2537 | H29: =G29/$G$41 -> 0.046249202 | J29: Decor | K29: 415724 | L29: =K29/$K$30 -> 0.22713609
B30: Laptop | C30: 323895 | D30: =C30/$C$33 -> 0.17696415 | F30: Raipur | G30: 2217 | H30: =G30/$G$41 -> 0.040415641 | J30: TOTAL | K30: =SUM(_xlfn.ANCHORARRAY(K27)) -> 1830286 | L30: =SUM(L27:L29) -> 1
B31: Suit | C31: 307377 | D31: =C31/$C$33 -> 0.16793933 | F31: Durgapur | G31: 2228 | H31: =G31/$G$41 -> 0.04061617
B32: Home décor | C32: 299665 | D32: =C32/$C$33 -> 0.16372578 | F32: Gwalior | G32: 1704 | H32: =G32/$G$41 -> 0.031063713
B33: TOTAL | C33: =SUM(_xlfn.ANCHORARRAY(C23)) -> 1830286 | D33: =C33/$C$33 -> 1 | F33: Jamshedpur | G33: 1713 | H33: =G33/$G$41 -> 0.031227782
F34: Siliguri | G34: 1404 | H34: =G34/$G$41 -> 0.02559475
F35: Mangalore | G35: 1107 | H35: =G35/$G$41 -> 0.020180476
F36: Thane | G36: 702 | H36: =G36/$G$41 -> 0.012797375
F37: Chandigarh | G37: 707 | H37: =G37/$G$41 -> 0.012888524
F38: Bhopal | G38: 712 | H38: =G38/$G$41 -> 0.012979674
F39: Visakhapatnam | G39: 717 | H39: =G39/$G$41 -> 0.013070823
F40: Patna | G40: 924 | H40: =G40/$G$41 -> 0.016844408
...

Sheet dashboard
AB8: #VALUE!
